Workbook

Sheet METAS 2025
A1: TIPO DE FECHAMETO | B1: CÓD META | C1: FECHAMENTO | D1: COD | E1: INICIO | F1: FIM | G1: PARÂMETRO | H1: PERÍODO FECHAMENTO | I1: META | J1: PERC DE PRÊMIO | K1: PRODUÇÃO MÊS | L1: CRÉDITO | M1: FILIAL | N1: GERENTE | O1: CHAMADO / E-MAIL | P1: DATA-CHAM/E-MAIL | Q1: OBS | R1: STATUS
A2: 1- AUTOMÁTICO | B2: 7917 | C2: 09 - SETEMBRO | D2: 15332 | E2: 45901 | F2: 45930 | G2: PRODUÇÃO GERAL BANCO MASTER | H2: MENSAL | I2: 0.01 | J2: 0.01 | O2: 1744553 | P2: 45874.467 | R2: TRUE
A3: 1- AUTOMÁTICO | B3: 7985 | C3: 09 - SETEMBRO | D3: 8465/ 1363/3728/3729 | E3: 45870 | F3: 45930 | G3: BANCO AMIGOZ/ PRODUTO TODOS E TABELAS TODAS | H3: BIMESTRAL | I3: 500000 | J3: 0.012 | O3: 1747448 | P3: 07/08/2025 18:08:59 | Q3: Ajustar datas | R3: Ajustar
A4: 1- AUTOMÁTICO | B4: 7985 | C4: 09 - SETEMBRO | D4: 8465/ 1363/3728/3729 | E4: 45870 | F4: 45930 | G4: BANCO AMIGOZ/ PRODUTO TODOS E TABELAS TODAS | H4: BIMESTRAL | I4: 1000000 | J4: 0.022 | O4: 1747448 | P4: 07/08/2025 18:08:59 | Q4: Ajustar datas | R4: Ajustar
A5: 2- MANUAL | B5: 8473 | C5: 09 - SETEMBRO | D5: 6218 | E5: 45889 | F5: 45930 | G5: TODA A PRODUÇÃO Obs: para bonificação nao serão considerados tabelas que possuem regras VIP aprovadas. | H5: FINAL DE CAMPANHA | I5: 0.01 | J5: 0.003 | O5: 1757082 | P5: 22/08/2025 14:16:07 | R5: TRUE
A6: 1- AUTOMÁTICO | B6: 8701 | C6: 09 - SETEMBRO | D6: 12156 | E6: 45901 | F6: 45930 | G6: PAN -PRODU??O TOTAL CONVENIO INSS | I6: 1000 | J6: 0.003 | O6: 1761547 | P6: 29/08/2025 09:38:39 | R6: TRUE
A7: 2- MANUAL | B7: 8506 | C7: 09 - SETEMBRO | D7: 17097 | E7: 45901 | F7: 45930 | G7: CONFORME REGRAS FACTA | H7: MENSAL | I7: 0.01 | J7: 0.006 | O7: 1762550 | P7: 01/09/2025 10:37:18 | R7: TRUE
A8: 1- AUTOMÁTICO | B8: 8524 | C8: 09 - SETEMBRO | D8: 16131 | E8: 45901 | F8: 45930 | G8: CASHCARD -Governo de Alagoas, Prefeitura de Natal ? Em cima de todas as tabelas e produtos | H8: MENSAL | I8: 1000 | J8: 0.015 | O8: 1762584 | P8: 01/09/2025 10:55:25 | R8: TRUE
A9: 1- AUTOMÁTICO | B9: 8531 | C9: 09 - SETEMBRO | D9: 17938 | E9: 45901 | F9: 45930 | G9: MERCANTIL-Iremos considerar toda a produção de cartões RCC e RMC. | H9: MENSAL | I9: 0.01 | J9: 0.01 | O9: 1763007 | P9: 01/09/2025 14:22:56 | R9: FALSE
A10: 1- AUTOMÁTICO | B10: 8523 | C10: 09 - SETEMBRO | D10: 12156 | E10: 45901 | F10: 45930 | G10: TODA PRODUCAO PAN | H10: MENSAL | I10: 1000 | J10: 0.003 | O10: 1763045 | P10: 01/09/2025 14:40:48 | R10: FALSE
A11: 1- AUTOMÁTICO | B11: 8522 | C11: 09 - SETEMBRO | D11: 12776 | E11: 45901 | F11: 45930 | G11: CREFAZ TODA PRODUCAO | H11: FINAL DA CAMPANHA | I11: 0.01 | J11: 0.002 | O11: 1763268 | P11: 01/09/2025 17:04:04 | R11: FALSE
A12: 1- AUTOMÁTICO | B12: 8520 | C12: 09 - SETEMBRO | D12: 14722 | E12: 45901 | F12: 45930 | G12: PRESENÇA BANK - INSS - NOVO | H12: FINAL DA CAMPANHA | I12: 10000 | J12: 0.005 | O12: 1763273 | P12: 01/09/2025 17:08:59 | R12: TRUE
A13: 2- MANUAL | B13: 8505 | C13: 09 - SETEMBRO | D13: 14722 | E13: 45901 | F13: 45930 | G13: FACTA - INSS - NOVO | H13: FINAL DA CAMPANHA | I13: 10000 | J13: 0.0075 | O13: 1763273 | P13: 01/09/2025 17:08:59 | R13: TRUE
A14: 1- AUTOMÁTICO | B14: 8521 | C14: 09 - SETEMBRO | D14: 14722 | E14: 45901 | F14: 45930 | G14: PAN - GOVERNO DE PERNAMBUCO NOVO E REFIN | H14: FINAL DA CAMPANHA | I14: 10000 | J14: 0.005 | O14: 1763273 | P14: 01/09/2025 17:08:59 | R14: TRUE
A15: 1- AUTOMÁTICO | B15: 8516 | C15: 09 - SETEMBRO | D15: 12288 | E15: 45901 | F15: 45930 | G15: CREFAZ -PRODUCAO TOTAL | H15: MENSAL | I15: 0.01 | J15: 0.002 | O15: 1763294 | P15: 01/09/2025 17:10:48 | R15: FALSE
A16: 1- AUTOMÁTICO | B16: 8517 | C16: 09 - SETEMBRO | D16: 12288 | E16: 45901 | F16: 45930 | G16: BANCO OLÉ INSS ? CARTÕES RMC E RCC ? PRODUCAO TOTAL | H16: MENSAL | I16: 0.01 | J16: 0.002 | O16: 1763294 | P16: 01/09/2025 17:10:48 | R16: FALSE
A17: 1- AUTOMÁTICO | B17: 8518 | C17: 09 - SETEMBRO | D17: 12288 | E17: 45901 | F17: 45930 | G17: BANCO SAFRA - TODA OPERAÇÃO NOVA | H17: MENSAL | I17: 0.01 | J17: 0.002 | O17: 1763294 | P17: 01/09/2025 17:10:48 | R17: FALSE
A18: 1- AUTOMÁTICO | B18: 8519 | C18: 09 - SETEMBRO | D18: 12288 | E18: 45901 | F18: 45930 | G18: BANCO MEU CREDBANK TODA PRODUÇÃO | H18: MENSAL | I18: 0.01 | J18: 0.005 | O18: 1763294 | P18: 01/09/2025 17:10:48 | R18: FALSE
... A30: 2- MANUAL | B30: 8502 | C30: 09 - SETEMBRO | D30: 13929 | E30: 45901 | F30: 45930 | G30: CONFORME REGRAS FACTA | H30: MENSAL | I30: 10000 | J30: 0.006 | O30: 1763579 | P30: 02/09/2025 10:00:38 | R30: TRUE
A31: 1- AUTOMÁTICO | B31: 8508 | C31: 09 - SETEMBRO | D31: 15818 / 16763 | E31: 45901 | F31: 45930 | G31: PRODUCAO TOTAL BANCO MASTER | H31: MENSAL | I31: 0.01 | J31: 0.015 | O31: 1763583 | P31: 02/09/2025 10:02:09 | Q31: credito 16763 | R31: FALSE
A32: 1- AUTOMÁTICO | B32: 8508 | D32: 15818 / 16763 | E32: 45901 | F32: 45930 | G32: PRODUCAO TOTAL BANCO MASTER | H32: MENSAL | I32: 1000000 | J32: 0.017 | O32: 1763583 | P32: 02/09/2025 10:02:09 | Q32: credito 16763 | R32: FALSE
A33: 2- MANUAL | B33: 8501 | C33: 09 - SETEMBRO | D33: 8835 | E33: 45901 | F33: 45930 | G33: CONFORME REGRAS FACTA | H33: MENSAL | I33: 10000 | J33: 0.006 | O33: 1763612 | P33: 02/09/2025 10:17:12 | R33: TRUE
A34: 2- MANUAL | B34: 8500 | C34: 09 - SETEMBRO | D34: 17614 | E34: 45901 | F34: 45930 | G34: CONFORME REGRAS FACTA | H34: MENSAL | I34: 10000 | J34: 0.0075 | O34: 1763618 | P34: 02/09/2025 10:22:53 | R34: TRUE
A35: 1- AUTOMÁTICO | B35: 8530 | C35: 09 - SETEMBRO | D35: 12466 | E35: 45901 | F35: 45930 | G35: QUERO MAIS CRÉDITO (SUBSTABELECIDO) | H35: MENSAL | I35: 0.01 | J35: 0.015 | O35: 1763627 | P35: 02/09/2025 10:28:22 | R35: TRUE
A36: 2- MANUAL | B36: 8497 | C36: 09 - SETEMBRO | D36: 13611 | E36: 45901 | F36: 45930 | G36: FACTA – PRODUÇÃO TOTAL CONFORME REGRA DE FECHAMENTO DO BANCO. | H36: MENSAL | I36: 0.01 | J36: 0.0075 | O36: 1763627 | P36: 02/09/2025 10:28:22 | R36: TRUE
A37: 1- AUTOMÁTICO | B37: 8511 | C37: 09 - SETEMBRO | D37: 13611 | E37: 45901 | F37: 45930 | G37: C6 – PRODUÇÃO TOTAL | H37: MENSAL | I37: 0.01 | J37: 0.002 | O37: 1763627 | P37: 02/09/2025 10:28:22 | R37: TRUE
A38: 2- MANUAL | B38: 8529 | C38: 09 - SETEMBRO | D38: 16029 | E38: 45901 | F38: 45930 | G38: BMG – OPERAÇÕES DE CARTÕES RMC E RCC – TODAS AS TABELAS DE SAQUE COMPLEMENTAR. | H38: MENSAL | I38: 0.01 | J38: 0.005 | O38: 1763627 | P38: 02/09/2025 10:28:22 | R38: TRUE
A39: 1- AUTOMÁTICO | B39: 8507 | C39: 09 - SETEMBRO | D39: 16029 | E39: 45901 | F39: 45930 | G39: BANCO MASTER – TODOS OS PRODUTOS E CONVENIOS. | H39: MENSAL | I39: 0.01 | J39: 0.015 | O39: 1763627 | P39: 02/09/2025 10:28:22 | R39: TRUE
A40: 2- MANUAL | B40: 8528 | C40: 09 - SETEMBRO | D40: 16029 | E40: 45901 | F40: 45930 | G40: BANCO DAYCOVAL – Englobar todos os prazos, produtos e convenios que possuam campanha ativa. | H40: MENSAL | I40: 0.01 | J40: 50% DO QUE FOR REPASSADO PELO BANCO. | O40: 1763627 | P40: 02/09/2025 10:28:22 | R40: TRUE
A41: 2- MANUAL | B41: 8498 | C41: 09 - SETEMBRO | D41: 16029 | E41: 45901 | F41: 45930 | G41: FACTA – PRODUÇÃO TOTAL CONFORME REGRA DE FECHAMENTO DO BANCO | H41: MENSAL | I41: 0.01 | J41: 0.0075 | O41: 1763627 | P41: 02/09/2025 10:28:22 | R41: TRUE
A42: 2- MANUAL | B42: 8499 | C42: 09 - SETEMBRO | D42: 17514 | E42: 45901 | F42: 45930 | G42: FACTA – PRODUÇÃO TOTAL CONFORME REGRA DE FECHAMENTO DO BANCO. | H42: MENSAL | I42: 0.01 | J42: 0.0075 | O42: 1763627 | P42: 02/09/2025 10:28:22 | R42: TRUE
A43: 2- MANUAL | B43: 8496 | C43: 09 - SETEMBRO | D43: 17711 | E43: 45901 | F43: 45930 | G43: CONFORME REGRAS FACTA | H43: MENSAL | I43: 10000 | J43: 0.0075 | O43: 1763628 | P43: 02/09/2025 10:28:44 | R43: TRUE
A44: 2- MANUAL | B44: 8495 | C44: 09 - SETEMBRO | D44: 16474 | E44: 45901 | F44: 45930 | G44: CONFORME REGRAS FACTA | H44: MENSAL | I44: 0.01 | J44: 0.005 | O44: 1763639 | P44: 02/09/2025 10:32:47 | R44: TRUE
A45: 1- AUTOMÁTICO | B45: 8558 | C45: 09 - SETEMBRO | D45: 15966 | E45: 45901 | F45: 45930 | G45: EM TODOS OS PRODUTOS E TABELAS BANCO MASTER | H45: MENSAL | I45: 10000 | J45: 0.016 | O45: 1763651 | P45: 02/09/2025 10:36:55 | R45: FALSE
A46: 1- AUTOMÁTICO | B46: 8557 | C46: 09 - SETEMBRO | D46: 13782 | E46: 45901 | F46: 45930 | G46: EM TODOS OS PRODUTOS E TABELAS BANCO AMIGOZ | H46: MENSAL | I46: 10000 | J46: 0.04 | O46: 1763667 | P46: 02/09/2025 10:43:07 | R46: FALSE
A47: 2- MANUAL | B47: 8556 | C47: 09 - SETEMBRO | D47: 14452 | E47: 45901 | F47: 45930 | G47: EM TODOS OS PRODUTOS E TABELAS BANCO DAYCOVAL QUE COMTEMPLAM A CAMPANHA DE BONUS | H47: MENSAL | I47: 10000 | J47: 0.007 | O47: 1763671 | P47: 02/09/2025 10:46:45 | R47: TRUE
A48: 2- MANUAL | B48: 8555 | C48: 09 - SETEMBRO | D48: 16898 | E48: 45901 | F48: 45930 | G48: CONFORME REGRAS FACTA | H48: MENSAL | I48: 0.01 | J48: 0.0045 | O48: 1763679 | P48: 02/09/2025 10:50:14 | R48: TRUE
A49: 2- MANUAL | B49: 8554 | C49: 09 - SETEMBRO | D49: 17859 e 17918 | E49: 45901 | F49: 45930 | G49: CONFORME REGRAS FACTA | H49: MENSAL | I49: 0.01 | J49: 0.006 | O49: 1763690 | P49: 02/09/2025 10:54:34 | Q49: 17918 | R49: TRUE
A50: 1- AUTOMÁTICO | B50: 8553 | C50: 09 - SETEMBRO | D50: 15874 | E50: 45901 | F50: 45930 | G50: QUERO MAIS/ TODAS AS TABELAS E TODOS OS CONV?NIOS | H50: MENSAL | I50: 0.01 | J50: 0.005 | O50: 1763699 | P50: 02/09/2025 10:58:16 | R50: FALSE
A51: 1- AUTOMÁTICO | B51: 8552 | C51: 09 - SETEMBRO | D51: 17865 | E51: 45901 | F51: 45930 | G51: toda produ??o de cartao e cartao beneficio do banco amigoz | H51: MENSAL | I51: 50000 | J51: 0.005 | O51: 1763700 | P51: 02/09/2025 10:58:40 | R51: FALSE
...

Sheet FILTRO
A1: CÓD CHAMADO | C1: CHAMADO
C2: COD CORRETOR | D2: PERIODO | E2: PARÂMETRO | F2: META | G2: PERC DE PRÊMIO | H2: MENSAGEM
A3: 1763007 | C3: {=_xlfn._xlws.FILTER(CHAMADOS!$I2:$I1500,CHAMADOS!$A2:$A1500=$A3,"Erro")} -> 17938 | D3: {=_xlfn._xlws.FILTER(CHAMADOS!$M2:$M1500,CHAMADOS!$A2:$A1500=$A3,"Erro")} -> 01/09 a 31/12 | E3: {=_xlfn._xlws.FILTER(CHAMADOS!$K2:$K1500,CHAMADOS!$A2:$A1500=$A3,"Erro")} -> DESCRI?AO | F3: {=_xlfn._xlws.FILTER(CHAMADOS!$J2:$J1500,CHAMADOS!$A2:$A1500=$A3,"Erro")} -> SEM META | G3: {=_xlfn._xlws.FILTER(CHAMADOS!$L2:$L1500,CHAMADOS!$A2:$A1500=$A3,"Erro")} -> 0,20% | H3: {=_xlfn._xlws.FILTER(CHAMADOS!$O2:$O1500,CHAMADOS!$A2:$A1500=$A3,"Erro")} -> Remetente - () Boa tarde! Iremos considerar toda a produção de cartões RCC e RMC. CODIGO DO CORRETOR: 17938 PERIODO: 01/09 a 31/12 TIPO DE FECHAMENTO: MENSAL META: SEM META PERCENTUAL DE PREMIO: 0,20% PARAMETRO: DESCRIÇAO ; Remetente - () Josi, boa tarde. Campanha parametrizada. Meta 8531,8532,8533,8534 ; Remetente - () Bom dia! Por gentielza alterar o percentual da camapanha. PERCENTUAL DE PREMIO: 0,40% PERIODO: 01/09 a 31/12; | I3: {=_xlfn.TEXTSPLIT(H3,";",";")} -> Remetente - () Boa tarde! Iremos considerar toda a produção de cartões RCC e RMC. CODIGO DO CORRETOR: 17938 PERIODO: 01/09 a 31/12 TIPO DE FECHAMENTO: MENSAL META: SEM META PERCENTUAL DE PREMIO: 0,20% PARAMETRO: DESCRIÇAO | J3: Remetente - () Josi, boa tarde. Campanha parametrizada. Meta 8531,8532,8533,8534 | K3: Remetente - () Bom dia! Por gentielza alterar o percentual da camapanha. PERCENTUAL DE PREMIO: 0,40% PERIODO: 01/09 a 31/12
C5: PLANILHA
C6: COD | D6: PERIODO | E6: PARÂMETRO | F6: META | G6: PERC DE PRÊMIO | H6: TIPO | I6: CÓD META
A7: VOLTAR | C7: {=_xlfn._xlws.FILTER('METAS 2025'!$D2:$D238,'METAS 2025'!$O2:$O238=$A$3)} -> 17938 | D7: {=_xlfn.CONCAT( TEXT(_xlfn._xlws.FILTER('METAS 2025'!$E2:$E238,'METAS 2025'!$O2:$O238=$A$3),"dd/mm/aaaa"), " a ", TEXT(_xlfn._xlws.FILTER('METAS 2025'!$F2:$F238,'METAS 2025'!$O2:$O238=$A$3),"dd/mm/aaaa"))} -> 01/09/2025 a 30/09/2025 | E7: {=_xlfn._xlws.FILTER('METAS 2025'!$G2:$G238,'METAS 2025'!$O2:$O238=$A$3)} -> MERCANTIL-Iremos considerar toda a produção de cartões RCC e RMC. | F7: {=_xlfn._xlws.FILTER('METAS 2025'!$I2:$I238,'METAS 2025'!$O2:$O238=$A$3)} -> 0.01 | G7: {=_xlfn._xlws.FILTER('METAS 2025'!$J2:$J238,'METAS 2025'!$O2:$O238=$A$3)} -> 0.01 | H7: {=_xlfn._xlws.FILTER('METAS 2025'!$H2:$H238,'METAS 2025'!$O2:$O238=$A$3)} -> MENSAL | I7: {=_xlfn._xlws.FILTER('METAS 2025'!$B2:$B238,'METAS 2025'!$O2:$O238=$A$3)} -> 8531

Sheet CHAMADOS
A1: COD. CHAMADO | B1: CATEGORIA | C1: TITULO | D1: SOLICITANTE | E1: RESPONSAVEL | F1: SITUACAO | G1: DATA ULTIMA MENSAGEM | H1: DATA CHAMADO | I1: CODIGO DO CORRETOR | J1: META | K1: PARAMETRO | L1: PERCENTUAL DE PREMIO | M1: PERIODO | N1: TIPO DE FECHAMENTO | O1: MENSAGEM
A2: 1774323 | B2: PARAMETRIZACAO DE CAMPANHA | C2: PARAMETRIZAR CAMPANHA - ID | D2: JOSIANE ARAUJO TEIXEIRA (U) | E2: Cinthia Gomes da Silva | F2: Aberto | G2: 24/09/2025 10:51:14 | H2: 17/09/2025 15:45:46 | I2: 3349 / 11938 | J2: DESCRI?AO | K2: DESCRI?AO | L2: DESCRI??O | M2: 01/09 a 30/09 | N2: MENSAL | O2: Remetente - () Boa tarde! Parametro: Toda a produção paga da parceira será contabilizada independente do produto para o atingimento da meta . Porém a bonificação nas duas escalas seja 0.10% ou 0.20% dependendo da meta atingida conforme pleito acima só deverá ser paga sobre a produção de contratos novos / convênio Inss / prazo máximo 84 meses / tabela normal com exceção do banco Itaú ( pois está na regra VIP) Lembrando que a campanha em questão contempla a soma dos 2 códigos que a parceira tem conosco ID 3349 / ID 11938. Meta / bonificação 300.000,00 - 0,10 500.000,00 - 0,20 Abonificação sera paga no codigo ID 3349 CODIGO DO CORRETOR: 3349 / 11938 PERIODO: 01/09 A 30/09 TIPO DE FECHAMENTO: MENSAL META: DESCRIÇAO PERCENTUAL DE PREMIO: DESCRIÇÃO PARAMETRO: DESCRIÇAO ; Remetente - () Josi, bom dia. Reforço que não tem como considerar tabela normal de todos bancos, pois cada um possui sua particularidade. ; Remetente - () Em tempo Portanto foi considerados todas as tabelas do INSS-NOVO- 84X;
A3: 1778432 | B3: PARAMETRIZACAO DE CAMPANHA | C3: CAMPANHA SETEMBRO I COD 9132 I BANCO DIGIO | D3: BIANCA CRISTIANE SOARES SANTOS TERENCIO (U) | F3: Aberto | G3: 24/09/2025 10:00:40 | H3: 24/09/2025 10:00:40 | I3: 9132 | J3: 1.000,00 | K3: anco Digio ? Todos os Produtos ? Todos os Prazos ? Conv?nio INSS ? Todas as Tabelas | L3: 0,20 | M3: 22/09 A 30/09 | N3: MENSAL | O3: Remetente - () Bom dia ! Gentileza parametrizar conforme solicitado. Banco Digio ? Todos os Produtos ? Todos os Prazos ? Convênio INSS ? Todas as Tabelas CODIGO DO CORRETOR: 9132 PERIODO: 22/09 A 30/09 TIPO DE FECHAMENTO: MENSAL META: 1.000,00 PERCENTUAL DE PREMIO: 0,20 PARAMETRO: anco Digio ? Todos os Produtos ? Todos os Prazos ? Convênio INSS ? Todas as Tabelas ;
A4: 1778429 | B4: PARAMETRIZACAO DE CAMPANHA | C4: PARAMAETRIZAR CAMPANHA BANCO PAN - ID 15503 | D4: JOSIANE ARAUJO TEIXEIRA (U) | F4: Aberto | G4: 24/09/2025 09:56:34 | H4: 24/09/2025 09:56:34 | I4: 15503 | J4: SEM META | K4: toda a produ??o de CONVENIOS PUBLICOS | L4: 0,40% | M4: 01/09 a 30/09 | N4: MENSAL | O4: Remetente - () Bom dia! CODIGO DO CORRETOR: 15503 PERIODO: 01/09 A 30/09 TIPO DE FECHAMENTO: MENSAL META: SEM META PERCENTUAL DE PREMIO: 0,40% PARAMETRO: toda a produção de CONVENIOS PUBLICOS ;
A5: 1772674 | B5: PARAMETRIZACAO DE CAMPANHA | C5: PARAMETRIZAR CAMPANHA - ID 6448 / 8737 | D5: JOSIANE ARAUJO TEIXEIRA (U) | E5: Cinthia Gomes da Silva | F5: Aberto | G5: 24/09/2025 09:10:23 | H5: 16/09/2025 09:42:36 | I5: 6448 / 8737 | J5: 760.000,00 | K5: TODAS AS TABELAS E PRODUTOS. DESCONSIDERAR PORT, VIP, E GRUPO 001 P/ CALCULO DO B?NUS | L5: 0,30% | M5: 01/08 A 30/09 | N5: TRIMESTRAL | O5: Remetente - () Bom dia! A bonificação sera paga no codigo ID 6448 CODIGO DO CORRETOR: 6448 / 8737 PERIODO: 01/08 A 30/09 TIPO DE FECHAMENTO: TRIMESTRAL META: 760.000,00 PERCENTUAL DE PREMIO: 0,30% PARAMETRO: TODAS AS TABELAS E PRODUTOS. DESCONSIDERAR PORT, VIP, E GRUPO 001 P/ CALCULO DO BÔNUS ; Remetente - () Boa tarde! PARAMETRO: TODAS AS TABELAS E PRODUTOS DE TODOS OS BANCO ( DESCONSIDERAR PORT, VIP, E GRUPO 001 P/ CALCULO DO BÔNUS ); Remetente - () Josi, boa tarde. Campanha parametrizada. codigo 8807 ; Remetente - () Prezados, bom dia! Favor desativar campanha. ;
A6: 1777951 | B6: PARAMETRIZACAO DE CAMPANHA | C6: CAMPANHA FACTA I 14034 | D6: BARBARA VIRGINIA RAIMUNDI DE SIQUEIRA (U) | F6: Aberto | G6: 23/09/2025 14:35:53 | H6: 23/09/2025 14:33:20 | I6: 14034 | J6: SEM META | K6: CONFORME REGRAS FACTA | L6: 0,50% | M6: 01/09 a 30/09 | N6: MENSAL | O6: Remetente - () Prezados(a), boa tarde ! Gentileza parametrizar campanha conforme solicitado pela GC Larissa Sobral e diretor Danilo Ferreira. CODIGO DO CORRETOR: 14034 PERIODO: 01/09 À 30/09 TIPO DE FECHAMENTO: MENSAL META: SEM META PERCENTUAL DE PREMIO: 0,50% PARAMETRO: CONFORME REGRAS FACTA ; Remetente - () considerar o código 13819 (Leandro José) para essa campanha. ;
A7: 1777949 | B7: PARAMETRIZACAO DE CAMPANHA | C7: CAMPANHA FACTA I 14034 | D7: BARBARA VIRGINIA RAIMUNDI DE SIQUEIRA (U) | F7: Aberto | G7: 23/09/2025 14:33:10 | H7: 23/09/2025 14:33:10 | I7: 14034 | J7: SEM META | K7: CONFORME REGRAS FACTA | L7: 0,50% | M7: 01/09 a 30/09 | N7: MENSAL | O7: Remetente - () Prezados(a), boa tarde ! Gentileza parametrizar campanha conforme solicitado pela GC Larissa Sobral e diretor Danilo Ferreira. CODIGO DO CORRETOR: 14034 PERIODO: 01/09 À 30/09 TIPO DE FECHAMENTO: MENSAL META: SEM META PERCENTUAL DE PREMIO: 0,50% PARAMETRO: CONFORME REGRAS FACTA ;
A8: 1777943 | B8: PARAMETRIZACAO DE CAMPANHA | C8: CAMPANHA FACTA I 13440 | D8: BARBARA VIRGINIA RAIMUNDI DE SIQUEIRA (U) | F8: Aberto | G8: 23/09/2025 14:29:41 | H8: 23/09/2025 14:29:41 | I8: 13440 | J8: SEM META | K8: CONFORME REGRAS FACTA | L8: 0,75% | M8: 01/09 a 30/09 | N8: MENSAL | O8: Remetente - () Prezados(a), boa tarde ! Gentileza parametrizar conforme solicitado pela GC Larissa Sobral e e acordado pelo Danilo Ferreira. CODIGO DO CORRETOR: 13440 PERIODO: 01/09 À 30/09 TIPO DE FECHAMENTO: MENSAL META: SEM META PERCENTUAL DE PREMIO: 0,75% PARAMETRO: CONFORME REGRAS FACTA ;
A9: 1777578 | B9: PARAMETRIZACAO DE CAMPANHA | C9: CAMPANHA SETEMBRO I COD 15692 I DAYCOVAL | D9: BIANCA CRISTIANE SOARES SANTOS TERENCIO (U) | F9: Aberto | G9: 23/09/2025 10:19:13 | H9: 23/09/2025 10:19:13 | I9: 15692 | J9: SEM META | K9: EM CIMA DA PRODU??O TOTAL | L9: 0,70 | M9: 01/09 a 30/09 | N9: MENSAL | O9: Remetente - () Bom dia! Gentileza parametrizar conforme solicitado. CODIGO DO CORRETOR: 15692 PERIODO: 01/09 A 30/09 TIPO DE FECHAMENTO: MENSAL META: SEM META PERCENTUAL DE PREMIO: 0,70 PARAMETRO: EM CIMA DA PRODUÇÃO TOTAL ;
A10: 1777521 | B10: PARAMETRIZACAO DE CAMPANHA | C10: CAMPANHA SETEMBRO I COD 14011 I VCTEX | D10: BIANCA CRISTIANE SOARES SANTOS TERENCIO (U) | F10: Aberto | G10: 23/09/2025 10:01:49 | H10: 23/09/2025 10:01:49 | I10: 14011 | J10: SEM META | K10: TUDO O QUE PRODUZIR NA TABELA EXP | L10: 1,0 | M10: 01/09 a 30/09 | N10: MENSAL | O10: Remetente - () Bom dia! Gentileza parametrizar conforme solicitado. TUDO O QUE PRODUZIR NA TABELA EXP -FGTS CODIGO DO CORRETOR: 14011 PERIODO: 01/09 A 30/09 TIPO DE FECHAMENTO: MENSAL META: SEM META PERCENTUAL DE PREMIO: 1,0 PARAMETRO: TUDO O QUE PRODUZIR NA TABELA EXP ;
A11: 1774925 | B11: PARAMETRIZACAO DE CAMPANHA | C11: CAMPANHA BANCO VCTEX l CÓDIGO 18307 l GC LAIS PASCOAL | D11: FABIULA RODRIGUES ARAUJO ZANONI (U) | F11: Aberto | G11: 23/09/2025 09:54:18 | H11: 18/09/2025 11:45:08 | I11: 18307 | J11: 1,00 | K11: PRODU??O BANCO VCTEX | L11: 1,00% | M11: 01/09 a 30/09 | N11: MENSAL | O11: Remetente - () Suporte, bom dia! Gentileza cadastrar campanha solicitada pela Lais e de acordo do Danilo, planilha em anexo. CODIGO DO CORRETOR: 18307 PERIODO: 01/09/2025 a 30/09/2025 TIPO DE FECHAMENTO: MENSAL META: 1,00 PERCENTUAL DE PREMIO: 1,00% PARAMETRO: PRODUÇÃO BANCO VCTEX ; Remetente - () Novo arquivo enviado: CAMPANHAVCTEXFILIPEVS_2025_09_18_11_45_08.xlsx; Remetente - () Novo arquivo enviado: CAMPANHAVCTEXFILIPEVS_2025_09_18_11_45_08_2025_09_23_09_54_18.xlsx; Remetente - () Suporte, bom dia! Segue planilha atualizada para campanha.;
A12: 1777491 | B12: PARAMETRIZACAO DE CAMPANHA | C12: CAMPANHA SETEMBRO I BANCO FACTA I MULTILOJA I 18297/18312/18343 | D12: BIANCA CRISTIANE SOARES SANTOS TERENCIO (U) | F12: Aberto | G12: 23/09/2025 09:47:41 | H12: 23/09/2025 09:47:41 | I12: 18297/18312/18343 | J12: 20.000,00 | K12: CONFORME REGRAS FACTA | L12: 0,75 | M12: 19/9 A 30/09 | N12: MENSAL | O12: Remetente - () Bom dia ! Gentileza parametrizar conforme solicitado. parametrizar as pagamentos para a empresa - G & D SOLUCOES DIGITAIS LTDA. cod 18297. CODIGO DO CORRETOR: 18297/18312/18343 PERIODO: 19/9 A 30/09 TIPO DE FECHAMENTO: MENSAL META: 20.000,00 PERCENTUAL DE PREMIO: 0,75 PARAMETRO: CONFORME REGRAS FACTA ;
A13: 1777482 | B13: PARAMETRIZACAO DE CAMPANHA | C13: CAMPANHA BANCO FACTA l CÓDIGO 18356 l GC LARISSA SOBRAL | D13: FABIULA RODRIGUES ARAUJO ZANONI (U) | F13: Aberto | G13: 23/09/2025 09:43:39 | H13: 23/09/2025 09:43:39 | I13: 18356 | J13: SEM META | K13: NAS TABELAS QUE ? NOS REPASSADO O BONUS | L13: 0,50% | M13: 01/09 a 30/09 | N13: MENSAL | O13: Remetente - () Suporte, bom dia! Gentileza cadastrar campanha solicitada pela Larissa e de acordo do Danilo, segue planilha em anexo. CODIGO DO CORRETOR: 18356 PERIODO: 01/09/2025 a 30/09/2025 TIPO DE FECHAMENTO: MENSAL META: SEM META PERCENTUAL DE PREMIO: 0,50% PARAMETRO: NAS TABELAS QUE É NOS REPASSADO O BONUS ; Remetente - () Novo arquivo enviado: BONUSFACTAPATRICIA(1)_2025_09_23_09_43_39.xlsx;
A14: 1777314 | B14: PARAMETRIZACAO DE CAMPANHA | C14: CAMPANHA BANCO BMG l CÓDIGO 16130 l GC CHRISTIANE NIELSEN | D14: FABIULA RODRIGUES ARAUJO ZANONI (U) | F14: Aberto | G14: 22/09/2025 17:29:54 | H14: 22/09/2025 17:29:54 | I14: 16130 | J14: 0,01 | K14: PRODU??O TOTAL NOVO CONV?NIO INSS | L14: 0,20% | M14: 19/09/2025 A 30/09/2025 | N14: MENSAL | O14: Remetente - () Suporte, boa tarde! Gentileza cadastrar campanha campanha solicitada pela Cris e de acordo do André. CODIGO DO CORRETOR: 16130 PERIODO: 19/09/2025 A 30/09/2025 TIPO DE FECHAMENTO: MENSAL META: 0,01 PERCENTUAL DE PREMIO: 0,20% PARAMETRO: PRODUÇÃO TOTAL NOVO CONVÊNIO INSS ;
A15: 1777286 | B15: PARAMETRIZACAO DE CAMPANHA | C15: CAMPANHA BANCO MASTER l CÓDIGO 6905 l GC ICARO FRANÇA | D15: FABIULA RODRIGUES ARAUJO ZANONI (U) | F15: Aberto | G15: 22/09/2025 17:02:52 | H15: 22/09/2025 17:02:52 | I15: 6905 | J15: 0,01 | K15: ?A campanha ? exclusiva para o produto M FACIL E CREDCESTA, no banco MASTER e conv?nio?prefeitura de UBERABA, IPSERV E CODAU em todas as tabelas e prazos. | L15: 1,23% | M15: 01/09 a 30/09 | N15: MENSAL | O15: Remetente - () Suporte, boa tarde! Gentileza cadastrar campanha solicitada pelo Icaro e de acordo do Danilo, segue planilha em anexo. CODIGO DO CORRETOR: 6905 PERIODO: 01/09/2025 a 30/09/2025 TIPO DE FECHAMENTO: MENSAL META: 0,01 PERCENTUAL DE PREMIO: 1,23% PARAMETRO: A campanha é exclusiva para o produto M FACIL E CREDCESTA, no banco MASTER e convênio prefeitura de UBERABA, IPSERV E CODAU em todas as tabelas e prazos. ; Remetente - () Novo arquivo enviado: PLANILHACAMPANHALUIZGUSTAVO6905SUBMASTER(2)(1)(1)_2025_09_22_17_02_52.xlsx;
A16: 1777277 | B16: PARAMETRIZACAO DE CAMPANHA | C16: CAMPANHA l CÓDIGO 14011 l GC LARISSA SOBRAL | D16: FABIULA RODRIGUES ARAUJO ZANONI (U) | F16: Aberto | G16: 22/09/2025 16:56:58 | H16: 22/09/2025 16:56:58 | I16: 14011 | J16: DIVERSOS | K16: DIVERSOS | L16: DIVERSOS | M16: 01/09 a 30/09 | N16: MENSAL | O16: Remetente - () Suporte, boa tarde! Gentileza cadastrar campanhas solicitadas pela Larissa e de acordo do Danilo, segue planilha em anexo. CODIGO DO CORRETOR: 14011 PERIODO: 01/09/2025 a 30/09/2025 TIPO DE FECHAMENTO: MENSAL META: DIVERSOS PERCENTUAL DE PREMIO: DIVERSOS PARAMETRO: DIVERSOS ; Remetente - () Novo arquivo enviado: BONUSFACTAFLAVIO(2)_2025_09_22_16_56_58.xlsx;
A17: 1777197 | B17: PARAMETRIZACAO DE CAMPANHA | C17: CAMPANHA BANCO FACTA l CÓDIGO 16578 l GC LARISSA SOBRAL | D17: FABIULA RODRIGUES ARAUJO ZANONI (U) | F17: Aberto | G17: 22/09/2025 16:04:56 | H17: 22/09/2025 16:04:56 | I17: 16578 | J17: SEM META | K17: NAS TABELAS QUE ? NOS REPASSADO O BONUS | L17: 0,30% | M17: 01/09 a 30/09 | N17: MENSAL | O17: Remetente - () Suporte, boa tarde! Gentileza cadastrar campanha solicitada pela Larissa e de acordo do Danilo, segue planilha em anexo. CODIGO DO CORRETOR: 16578 PERIODO: 01/09/2025 a 30/09/2025 TIPO DE FECHAMENTO: MENSAL META: SEM META PERCENTUAL DE PREMIO: 0,30% PARAMETRO: NAS TABELAS QUE É NOS REPASSADO O BONUS ; Remetente - () Novo arquivo enviado: BONUSFACTAGABRIELA_2025_09_22_16_04_56.xlsx;
... A34: 1776598 | B34: PARAMETRIZACAO DE CAMPANHA | C34: CAMPANHA BANCO FACTA l CÓDIGO 17143 l GC THAIS MELO | D34: FABIULA RODRIGUES ARAUJO ZANONI (U) | F34: Aberto | G34: 22/09/2025 10:02:14 | H34: 22/09/2025 10:02:14 | I34: 17143 | J34: 1,00 | K34: ( Conforme parametro?facta?) | L34: 0,25 | M34: 01/09 a 30/09 | N34: MENSAL | O34: Remetente - () Suporte, bom dia! Gentileza cadastrar campanha solicitada pela Thais e de acordo do Danilo, segue planilha em anexo. CODIGO DO CORRETOR: 17143 PERIODO: 01/09/2025 a 30/09/2025 TIPO DE FECHAMENTO: MENSAL META: 1,00 PERCENTUAL DE PREMIO: 0,25 PARAMETRO: ( Conforme parametro facta ) ; Remetente - () Novo arquivo enviado: PLANILHADEBONUS-FACTA_2025_09_22_10_02_14.xlsx;
A35: 1763007 | B35: PARAMETRIZACAO DE CAMPANHA | C35: PARAMETRIZAR CAMPANHA BANCO MERCANTIL - ID 17938 | D35: JOSIANE ARAUJO TEIXEIRA (U) | E35: Cinthia Gomes da Silva | F35: Aberto | G35: 22/09/2025 10:00:19 | H35: 01/09/2025 14:22:56 | I35: 17938 | J35: SEM META | K35: DESCRI?AO | L35: 0,20% | M35: 01/09 a 31/12 | N35: MENSAL | O35: Remetente - () Boa tarde! Iremos considerar toda a produção de cartões RCC e RMC. CODIGO DO CORRETOR: 17938 PERIODO: 01/09 a 31/12 TIPO DE FECHAMENTO: MENSAL META: SEM META PERCENTUAL DE PREMIO: 0,20% PARAMETRO: DESCRIÇAO ; Remetente - () Josi, boa tarde. Campanha parametrizada. Meta 8531,8532,8533,8534 ; Remetente - () Bom dia! Por gentielza alterar o percentual da camapanha. PERCENTUAL DE PREMIO: 0,40% PERIODO: 01/09 a 31/12;
A36: 1776588 | B36: PARAMETRIZACAO DE CAMPANHA | C36: CAMPANHA BANCO FACTA l CÓDIGO 15632 l GC THAIS MELO | D36: FABIULA RODRIGUES ARAUJO ZANONI (U) | F36: Aberto | G36: 22/09/2025 09:57:58 | H36: 22/09/2025 09:57:58 | I36: 15632 | J36: 1,00 | K36: ( Conforme parametro?facta?) | L36: 0,50 | M36: 01/09 a 30/09 | N36: MENSAL | O36: Remetente - () Suporte, bom dia! Gentileza cadastrar campanha solicitada pela Thais e de acordo do Danilo, segue planilha em anexo. CODIGO DO CORRETOR: 15632 PERIODO: 01/09/2025 a 30/09/2025 TIPO DE FECHAMENTO: MENSAL META: 1,00 PERCENTUAL DE PREMIO: 0,50 PARAMETRO: ( Conforme parametro facta ) ; Remetente - () Novo arquivo enviado: PLANILHADEBONUS-FACTAJUSUBj_2025_09_22_09_57_58.xlsx;
A37: 1776530 | B37: PARAMETRIZACAO DE CAMPANHA | C37: CAMPANHA BANCO C6 l CÓDIGO 11820 l GC THAYS MELO | D37: FABIULA RODRIGUES ARAUJO ZANONI (U) | F37: Aberto | G37: 22/09/2025 09:25:54 | H37: 22/09/2025 09:25:54 | I37: 11820 | J37: 1,00 | K37: DIVERSOS | L37: DIVERSOS | M37: 01/09 a 30/09 | N37: MENSAL | O37: Remetente - () Suporte, bom dia! Gentileza cadastrar campanha solicitada pela Thays e de acordo do Danilo, ressaltamos que a campanha e fechamento e enviada pelo Banco mensalmente. Segue planilha em anexo. CODIGO DO CORRETOR: 11820 PERIODO: 01/09/2025 a 30/09/2025 TIPO DE FECHAMENTO: MENSAL META: 1,00 PERCENTUAL DE PREMIO: DIVERSOS PARAMETRO: DIVERSOS ; Remetente - () Novo arquivo enviado: PLANILHADEBONUS-C6-TULIO_2025_09_22_09_25_54.xlsx;
A38: 1776525 | B38: PARAMETRIZACAO DE CAMPANHA | C38: CAMPANHA BANCO MASTER l CÓDIGO 15216 l GC THAIS MELO | D38: FABIULA RODRIGUES ARAUJO ZANONI (U) | F38: Aberto | G38: 22/09/2025 09:18:23 | H38: 22/09/2025 09:18:23 | I38: 15216 | J38: 1,00 | K38: TODA PRODU??O BANCO MASTER , DE ACORDO COM AS REGRAS DO BANCO | L38: 1,50 | M38: 01/09 a 30/09 | N38: MENSAL | O38: Remetente - () Suporte, bom dia! Gentileza cadastrar campanha solicitada pela Thais e de acordo do Danilo, segue planilha em anexo. CODIGO DO CORRETOR: 15216 PERIODO: 01/09/2025 a 30/09/2025 TIPO DE FECHAMENTO: MENSAL META: 1,00 PERCENTUAL DE PREMIO: 1,50 PARAMETRO: TODA PRODUÇÃO BANCO MASTER , DE ACORDO COM AS REGRAS DO BANCO ; Remetente - () Novo arquivo enviado: PLANILHADEBONUS-TOTEMMASTER_2025_09_22_09_18_23.xlsx;
A39: 1776512 | B39: PARAMETRIZACAO DE CAMPANHA | C39: CAMPANHA BANCO MERCANTIL l CÓDIGO 17740 l GC THAIS MELO | D39: FABIULA RODRIGUES ARAUJO ZANONI (U) | F39: Aberto | G39: 22/09/2025 09:11:10 | H39: 22/09/2025 09:11:10 | I39: 17740 | J39: 1,00 | K39: B?nus pago referente a venda de cart?o RMC E RCC | L39: 0,70 | M39: 01/09 a 30/09 | N39: MENSAL | O39: Remetente - () Suporte, bom dia! Gentileza cadastrar campanha solicitada pela Thais e de acordo do Danilo. Segue planilha em anexo. CODIGO DO CORRETOR: 17740 PERIODO: 01/09/2025 a 30/09/2025 TIPO DE FECHAMENTO: MENSAL META: 1,00 PERCENTUAL DE PREMIO: 0,70 PARAMETRO: Bônus pago referente a venda de cartão RMC E RCC ; Remetente - () Novo arquivo enviado: PLANILHADEBONUS-mercatiloliveira(1)_2025_09_22_09_11_10.xlsx;
A40: 1776346 | B40: PARAMETRIZACAO DE CAMPANHA | C40: PARAMETRIZAR CAMPANHA BANCO ID 13782 | D40: JOSIANE ARAUJO TEIXEIRA (U) | F40: Aberto | G40: 19/09/2025 16:35:27 | H40: 19/09/2025 16:35:27 | I40: 13782 | J40: 10 MIL | K40: EM TODOS OS PRODUTOS E TABELAS BANCO DAYCOVAL QUE COMTEMPLAM A CAMPANHA DE BONUS | L40: 1,2% | M40: 01/09 a 30/09 | N40: MENSAL | O40: Remetente - () Boa tarde! CODIGO DO CORRETOR: 13782 PERIODO: 01/09 A 30/09 TIPO DE FECHAMENTO: MENSAL META: 10 MIL PERCENTUAL DE PREMIO: 1,2% PARAMETRO: EM TODOS OS PRODUTOS E TABELAS BANCO DAYCOVAL QUE COMTEMPLAM A CAMPANHA DE BONUS ;
A41: 1776315 | B41: PARAMETRIZACAO DE CAMPANHA | C41: CAMPANHA BANCO VCTEX l CÓDIGO 16358 l FERNANDA OTONI | D41: FABIULA RODRIGUES ARAUJO ZANONI (U) | F41: Aberto | G41: 19/09/2025 16:11:05 | H41: 19/09/2025 16:11:05 | I41: 16358 | J41: 400.000,00 | K41: PRODUCAO TOTAL | L41: 0,25% | M41: 01/09 a 30/09 | N41: MENSAL | O41: Remetente - () Suporte, boa tarde! Gentileza cadastrar campanha solicitada pela Fernanda e de acordo do Danilo, segue planilha em anexo. CODIGO DO CORRETOR: 16358 PERIODO: 01/09/2025 a 30/09/2025 TIPO DE FECHAMENTO: MENSAL META: 400.000,00 PERCENTUAL DE PREMIO: 0,25% PARAMETRO: PRODUCAO TOTAL ; Remetente - () Novo arquivo enviado: CAMPANHAMESSETEMBROVCTEX(2)_2025_09_19_16_11_05.xlsx;
A42: 1776262 | B42: PARAMETRIZACAO DE CAMPANHA | C42: CAMPANHA FACTA l CÓDIGO 17051 l GC THAIS MELO | D42: FABIULA RODRIGUES ARAUJO ZANONI (U) | F42: Aberto | G42: 19/09/2025 15:32:16 | H42: 19/09/2025 15:32:16 | I42: 17051 | J42: 1,00 | K42: Conforme parametro?facta? | L42: 0,25 | M42: 01/09 a 30/09 | N42: MENSAL | O42: Remetente - () Suporte, boa tarde! Gentileza cadastrar campanha solicitada pela Thais e de acordo do Danilo, segue planilha em anexo. CODIGO DO CORRETOR: 17051 PERIODO: 01/09/2025 a 30/09/2025 TIPO DE FECHAMENTO: MENSAL META: 1,00 PERCENTUAL DE PREMIO: 0,25 PARAMETRO: Conforme parametro facta ; Remetente - () Novo arquivo enviado: PLANILHADEBONUS-FACTAMICHELLE(1)_2025_09_19_15_32_16.xlsx;
A43: 1776259 | B43: PARAMETRIZACAO DE CAMPANHA | C43: PARAMETRIZAR CAMPANHA BANCO - ID 7274 | D43: JOSIANE ARAUJO TEIXEIRA (U) | F43: Aberto | G43: 19/09/2025 15:28:10 | H43: 19/09/2025 15:28:10 | I43: 7274 | J43: SEM META | K43: PAN / INSS NOVO / TODAS AS TABELAS E PRAZOS | L43: 0,20 | M43: 18/09 A 30/09 | N43: MENSAL | O43: Remetente - () Boa tarde! CODIGO DO CORRETOR: 7274 PERIODO: 18/09 A 30/09 TIPO DE FECHAMENTO: MENSAL META: SEM META PERCENTUAL DE PREMIO: 0,20 PARAMETRO: PAN / INSS NOVO / TODAS AS TABELAS E PRAZOS ;
A44: 1776250 | B44: PARAMETRIZACAO DE CAMPANHA | C44: PARAMETIRZAÇAO DE CAMPANHA - ID 17303 | D44: JOSIANE ARAUJO TEIXEIRA (U) | F44: Aberto | G44: 19/09/2025 15:20:56 | H44: 19/09/2025 15:20:56 | I44: 17303 | J44: 1000 | K44: Banco Quero Mais Cr?dito ? Todos os Produtos , com EXCE??O INSS ? Todos os Prazos ? Todos os conv?nios ? Todas as Tabelas | L44: 1,9% | M44: 01/09 a 30/09 | N44: MENSAL | O44: Remetente - () Boa tarde! CODIGO DO CORRETOR: 17303 PERIODO: 01/09 A 30/09 TIPO DE FECHAMENTO: MENSAL META: 1000 PERCENTUAL DE PREMIO: 1,9% PARAMETRO: Banco Quero Mais Crédito ? Todos os Produtos , com EXCEÇÃO INSS ? Todos os Prazos ? Todos os convênios ? Todas as Tabelas ;
A45: 1776244 | B45: PARAMETRIZACAO DE CAMPANHA | C45: PARAMETRIZAR CAMPANHA - ID 14722 | D45: JOSIANE ARAUJO TEIXEIRA (U) | F45: Aberto | G45: 19/09/2025 15:13:38 | H45: 19/09/2025 15:13:38 | I45: 14722 | J45: 10.000,00 | K45: MERCANTIL ? PRODU??O DE FGTS | L45: 0,60% | M45: 18/09 A 30/09 | N45: MENSAL | O45: Remetente - () Boa tarde@! CODIGO DO CORRETOR: 14722 PERIODO: 18/09 A 30/09 TIPO DE FECHAMENTO: MENSAL META: 10.000,00 PERCENTUAL DE PREMIO: 0,60% PARAMETRO: MERCANTIL ? PRODUÇÃO DE FGTS ;
A46: 1776226 | B46: PARAMETRIZACAO DE CAMPANHA | C46: CAMPANHA BANCO FACTA l CÓDIGO 15516 l THAIS MELO | D46: FABIULA RODRIGUES ARAUJO ZANONI (U) | F46: Aberto | G46: 19/09/2025 15:02:46 | H46: 19/09/2025 15:02:46 | I46: 15516 | J46: 1,00 | K46: ( Conforme parametro?facta?) | L46: 0,50 | M46: 01/09 a 30/09 | N46: MENSAL | O46: Remetente - () Suporte, boa tarde! Gentileza cadastrar campanha solicitada pela Thais e de acordo do Danilo, segue planilha em anexo. CODIGO DO CORRETOR: 15516 PERIODO: 01/09/2025 a 30/09/2025 TIPO DE FECHAMENTO: MENSAL META: 1,00 PERCENTUAL DE PREMIO: 0,50 PARAMETRO: ( Conforme parametro facta ) ; Remetente - () Novo arquivo enviado: PLANILHADEBONUS-FACTASUBTAYLO_2025_09_19_15_02_46.xlsx;
A47: 1776219 | B47: PARAMETRIZACAO DE CAMPANHA | C47: CAMPANHA BANCO FACTA l CÓDIGO 12732 l GC THAIS MELO | D47: FABIULA RODRIGUES ARAUJO ZANONI (U) | F47: Aberto | G47: 19/09/2025 14:59:22 | H47: 19/09/2025 14:59:22 | I47: 12732 | J47: 1,00 | K47: ( Conforme parametro?facta?) | L47: 0,50 | M47: 01/09 a 30/09 | N47: MENSAL | O47: Remetente - () Suporte, boa tarde! Gentileza cadastrar campanha solicitada pela Thais e de acordo do Danilo, segue planilha em anexo. CODIGO DO CORRETOR: 12732 PERIODO: 01/09/2025 a 30/09/2025 TIPO DE FECHAMENTO: MENSAL META: 1,00 PERCENTUAL DE PREMIO: 0,50 PARAMETRO: ( Conforme parametro facta ) ; Remetente - () Novo arquivo enviado: PLANILHADEBONUS-FACTAehe_2025_09_19_14_59_22.xlsx;
... A114: 1774170 | B114: PARAMETRIZACAO DE CAMPANHA | C114: PARAMETRIZAR CAMPANHA - ID 3557 | D114: JOSIANE ARAUJO TEIXEIRA (U) | F114: Aberto | G114: 17/09/2025 14:28:54 | H114: 17/09/2025 14:28:54 | I114: 3557 | J114: SEM META | K114: Toda a produ??o FGTS MERCANTIL | L114: 0,10% | M114: 01/09 a 30/09 | N114: MENSAL | O114: Remetente - () Boa tarde! CODIGO DO CORRETOR: 3557 PERIODO: 01/09 A 30/09 TIPO DE FECHAMENTO: MENSAL META: SEM META PERCENTUAL DE PREMIO: 0,10% PARAMETRO: Toda a produção FGTS MERCANTIL ;
A115: 1775609 | B115: PARAMETRIZACAO DE CAMPANHA | C115: PARAMETRIZAR CAMPANHA - ID: 13113 | D115: LUCAS GUIMARAES EVARISTO (U) | F115: Fechado | H115: 19/09/2025 08:57:41 | I115: 13113 | J115: SEM META | K115: CONFORME DESCRI??O | L115: CONFORME DESCRI??O | M115: 01/09 a 30/09 | N115: MENSAL | O115: Remetente - () Prezados, bom dia! Favor parametrizar campanha conforme abaixo. BANCO CREDBANK - TODA PRODUÇÃO INSS e cartoes EXCETO AS TABELAS - MEU CREDBANK - INSS - MEU CREDBANK - INSS - FP - NORMAL - TX 1,85MEU CREDBANK - INSS - MEU CREDBANK - INSS - FP - SEGURO - TX 1,85 - BONUS DE 0,70%. BANCO CREDBANK - TODA PRODUÇÃO DE FGTS - BONUS DE 1,20% BANCO FACTA - TODA PRODUÇÃO CONFORME REGRA - BONUS 0,75%. CODIGO DO CORRETOR: 13113 PERIODO: 01/09/2025 a 30/09/2025 TIPO DE FECHAMENTO: MENSAL META: SEM META PERCENTUAL DE PREMIO: CONFORME DESCRIÇÃO PARAMETRO: CONFORME DESCRIÇÃO ; Remetente - () FAVOR DESCONSIDERAR; Remetente - () Chamado encerrado.;
A116: 1774262 | B116: PARAMETRIZACAO DE CAMPANHA | C116: CAMPANHA l CÓDIGO 11994 l GC LUCYANA MEDEIROS | D116: FABIULA RODRIGUES ARAUJO ZANONI (U) | E116: Cinthia Gomes da Silva | F116: Fechado | H116: 17/09/2025 15:18:49 | I116: 11994 | J116: 1000,00 | K116: DIVERSOS | L116: DIVERSOS | M116: 01/09 a 30/09 | N116: MENSA | O116: Remetente - () Suporte, boa tarde! Gentileza cadastrar campanha conforme solicitado pela Glauce e de acordo do André. Segue planilha em anexo. CODIGO DO CORRETOR: 11994 PERIODO: 01/09/2025 a 30/09/2025 TIPO DE FECHAMENTO: MENSA META: 1000,00 PERCENTUAL DE PREMIO: DIVERSOS PARAMETRO: DIVERSOS ; Remetente - () Novo arquivo enviado: CampanhaRGGlauce_2025_09_17_15_18_49.xlsx; Remetente - () Fabi, boa tarde. Campanha parametrizada. codigo8809 8819 8825 ;
A117: 1774253 | B117: PARAMETRIZACAO DE CAMPANHA | C117: CAMPANHA BANCO MERCANTIL l CODIGO 18118 l GC LUCYANA MEDEIROS | D117: FABIULA RODRIGUES ARAUJO ZANONI (U) | E117: Cinthia Gomes da Silva | F117: Fechado | H117: 17/09/2025 15:14:27 | I117: 18118 | J117: 1000,00 | K117: BANCO MERCANTIL - TODAS AS TABELAS, COM EXCE??O DO CP RESOLVE -INSS CREDITO PESSOAL | L117: 0,20% | M117: 01/09 a 30/09 | N117: MENSAL | O117: Remetente - () Suporte, boa tarde! Gentileza cadastrar campanha solicitada pela Glauce e de acordo com André. Segue planilha em anexo. CODIGO DO CORRETOR: 18118 PERIODO: 01/09/2025 a 30/09/2025 TIPO DE FECHAMENTO: MENSAL META: 1000,00 PERCENTUAL DE PREMIO: 0,20% PARAMETRO: BANCO MERCANTIL - TODAS AS TABELAS, COM EXCEÇÃO DO CP RESOLVE -INSS CREDITO PESSOAL ; Remetente - () Novo arquivo enviado: CampanhaRGGlauce_2025_09_17_15_14_27.xlsx; Remetente - () Fabi, boa tarde. Campanha parametrizada. codigo 8826 ;
A118: 1774250 | B118: PARAMETRIZACAO DE CAMPANHA | C118: PARAMETRIZAR CAMPANHA - ID 1452 | D118: JOSIANE ARAUJO TEIXEIRA (U) | E118: Cinthia Gomes da Silva | F118: Fechado | H118: 17/09/2025 15:13:22 | I118: 1452 | J118: 300 K | K118: A ?produ??o de todos os bancos e tabelas ser? levada em considera??o para pagamento de b?nus e atingimento DA META | L118: 0.10% | M118: 01/09 a 30/09 | N118: MENSAL | O118: Remetente - () Boa tarde! CODIGO DO CORRETOR: 1452 PERIODO: 01/09 A 30/09 TIPO DE FECHAMENTO: MENSAL META: 300 K PERCENTUAL DE PREMIO: 0.10% PARAMETRO: A produção de todos os bancos e tabelas será levada em consideração para pagamento de bônus e atingimento DA META ; Remetente - () Josi, boa tarde. Campanha parametrizada. codigo 8827 ; Remetente - () ; Remetente - () segue ;
A119: 1774245 | B119: PARAMETRIZACAO DE CAMPANHA | C119: CAMPANHA l CÓDIGO 17515 l GC ROMAGNOSI SOTERO | D119: FABIULA RODRIGUES ARAUJO ZANONI (U) | E119: Cinthia Gomes da Silva | F119: Fechado | H119: 17/09/2025 15:11:12 | I119: 17515 | J119: DIVERSOS | K119: DIVERSOS | L119: DIVESOS | M119: 01/09 a 30/09 | N119: MENS | O119: Remetente - () Suporte, boa tarde! Gentileza cadastrar campanha solicitada pela Glauce e de acordo com André. Segue planilha em anexo. CODIGO DO CORRETOR: 17515 PERIODO: 01/09/2025 a 30/09/2025 TIPO DE FECHAMENTO: MENS META: DIVERSOS PERCENTUAL DE PREMIO: DIVESOS PARAMETRO: DIVERSOS ; Remetente - () Novo arquivo enviado: CampanhaRGGlauce_2025_09_17_15_11_12.xlsx; Remetente - () Fabi, boa tarde. Campanha parametrizada. codigo 8820 8810 ;
A120: 1774239 | B120: PARAMETRIZACAO DE CAMPANHA | C120: PARAMETRIZAR CAMPANHA BANCO - id 12378 | D120: JOSIANE ARAUJO TEIXEIRA (U) | E120: Cinthia Gomes da Silva | F120: Fechado | H120: 17/09/2025 15:06:43 | I120: 12378 | J120: R$ 200.000 | K120: TODA A PRODU??O AMIGOZ | L120: 0,70% | M120: 01/09 a 30/09 | N120: MENSAL | O120: Remetente - () Boa tarde! CODIGO DO CORRETOR: 12378 PERIODO: 01/09 A 30/09 TIPO DE FECHAMENTO: MENSAL META: R$ 200.000 PERCENTUAL DE PREMIO: 0,70% PARAMETRO: TODA A PRODUÇÃO AMIGOZ ; Remetente - () Josi, boa tarde. Campanha parametrizada. codigo 8828 ;
A121: 1774234 | B121: PARAMETRIZACAO DE CAMPANHA | C121: CAMPANHA BANCO FACTA l CÓDIGO 17461 l DIEGO MOURA | D121: FABIULA RODRIGUES ARAUJO ZANONI (U) | E121: Cinthia Gomes da Silva | F121: Fechado | H121: 17/09/2025 15:04:08 | I121: 17461 | J121: 0,10 | K121: TODAS AS OPERA??ES CONFORME FACTA - COM EXCE??O CLT | L121: 0,75% | M121: 01/09 a 30/09 | N121: MENSAL | O121: Remetente - () Suporte, boa tarde! Gentileza cadastrar campanha conforme solicitado pela Glauce e de acordo do André. Segue planilha em anexo. CODIGO DO CORRETOR: 17461 PERIODO: 01/09/2025 a 30/09/2025 TIPO DE FECHAMENTO: MENSAL META: 0,10 PERCENTUAL DE PREMIO: 0,75% PARAMETRO: TODAS AS OPERAÇÕES CONFORME FACTA - COM EXCEÇÃO CLT ; Remetente - () Novo arquivo enviado: CampanhaRGGlauce_2025_09_17_15_04_08.xlsx; Remetente - () Fabi, boa tarde. Campanha parametrizada. codigo 8811 ;
A122: 1774224 | B122: PARAMETRIZACAO DE CAMPANHA | C122: CAMPANHA BANCO DAYCOVAL l CÓDIGO 7734 l GC DIEGO MOURA | D122: FABIULA RODRIGUES ARAUJO ZANONI (U) | E122: Cinthia Gomes da Silva | F122: Fechado | H122: 17/09/2025 15:00:15 | I122: 7734 | J122: 0,10 | K122: DAYCOVAL - 50% DO B?NUS QUE A CREDFRANCO RECEBER DO BANCO | L122: 0,50% | M122: 01/09 a 30/09 | N122: MENSAL | O122: Remetente - () Suporte, boa tarde! Gentileza cadastrar campanha conforme solicitado pela Glauce e de acordo do André. Segue planilha em anexo. CODIGO DO CORRETOR: 7734 PERIODO: 01/09/2025 a 30/09/2025 TIPO DE FECHAMENTO: MENSAL META: 0,10 PERCENTUAL DE PREMIO: 0,50% PARAMETRO: DAYCOVAL - 50% DO BÔNUS QUE A CREDFRANCO RECEBER DO BANCO ; Remetente - () Novo arquivo enviado: CampanhaRGGlauce_2025_09_17_15_00_15.xlsx; Remetente - () Fabi, boa tarde. Campanha parametrizada. codigo 8829 ;
...

Sheet AGO - 25
A1: 08 - AGOSTO | B1: QUANTIDADE DE METAS: | D1: =COUNTIF($C:$C,$A$1) -> 556
A2: TIPO DE FECHAMETO | B2: CÓD META | C2: FECHAMENTO | D2: COD | E2: INICIO | F2: FIM | G2: PARÂMETRO | H2: PERÍODO FECHAMENTO | I2: META | J2: PERC DE PRÊMIO | K2: PRODUÇÃO MÊS | L2: CRÉDITO | M2: FILIAL | N2: GERENTE | O2: CHAMADO / E-MAIL | P2: DATA-CHAM/E-MAIL | Q2: OBS
A3: 2- MANUAL | B3: 6194 | C3: 08 - AGOSTO | D3: 4310 | 13955 | E3: 45870 | F3: 45900 | G3: IREMOS CONSIDERAR TODA A PRODUÇÃO / EXCETO AS TABELAS QUE POSSUEM VIP | H3: MENSAL | I3: 300000 | J3: 0.004 | M3: FILIAL BH2 | N3: WANDA MARIA MARTINS | O3: PARAMETRIZAR CAMPNAHA - BANCO FACTA - ID 4310 /13955 | P3: 45728 | Q3: CREDITO PARA O 14603
A4: 1- AUTOMÁTICO | B4: 6209 | C4: 08 - AGOSTO | D4: 7934 | E4: 45870 | F4: 45900 | G4: TODO A PRODUÇÃO | H4: MENSAL | I4: 1000 | J4: 0.002 | M4: FILIAL JOAO PESSOA | N4: WELLINGTON DE MELO COUTINHO CHAVES | O4: PARAMETRIZAR CAMPANHA - ID 7934 - TODA A PRODUÇÃO | P4: 45734
A5: 1- AUTOMÁTICO | B5: 6246 | C5: 08 - AGOSTO | D5: 1729 | 8125 | E5: 45870 | F5: 45900 | G5: TODA A PRODUÇÃO | H5: MENSAL | I5: 600000 | J5: 0.005 | M5: FILIAL BH2 | N5: WANDA MARIA MARTINS | O5: PARAMETRIZAR CAMPANHA - ID: 1729 / 8125 - REF: MARÇO 2025 | P5: 45737 | Q5: CREDITO PARA O 1729
A6: 2- MANUAL | B6: calcular e informar no e-mail | C6: - | D6: 12765 | E6: 45870 | F6: 45900 | G6: TODA PRODUÇÃO - CASO ATINJA OU NÃO, APENAS RETORNAR NO E-MAIL COMUNICANDO A PRODUÇÃO | H6: MENSAL | I6: 1000000 | J6: 0 | M6: FILIAL VITORIA | N6: RAHYZA EUSTACHIO DA SILVA | O6: Re: Antecipação de valores RL Rangel Serviços LTDA - 12765 (Projeto de ampliação Call Center) | P6: 45740
A7: 2- MANUAL | B7: 6307 | C7: 08 - AGOSTO | D7: 14533 | E7: 45706 | F7: 45900 | G7: TODA A PRODUÇÃO DOS BANCOS:C6 , FACTA , PAN , DAYCOVAL ,MEU CRED BANK , AMIGOZ ,BMG --em agosto, caso a parceira atinja 50% da meta anual, iremos pagar 50% do Bônus. | H7: MENSAL | I7: 25000000 | J7: 0.0005 | M7: FILIAL SAO LUIZ | N7: WANDER CRISTIAN ANTUNES BARBOSA | O7: PARAMETRIZAR CAMPANHA - ID 14533 - PRODUÇÃO TOTAL | P7: 45748
A8: 1- AUTOMÁTICO | B8: 6381 | C8: 08 - AGOSTO | D8: 2911 | 11402 | E8: 45870 | F8: 45900 | G8: TODOS BANCOS - INSS / SIAPE - TODOS OS PRODUTOS - EXCETO REFIN - PRAZO DE 84x e 96x | H8: MENSAL | I8: 0.01 | J8: 0.002 | M8: FILIAL VITORIA | N8: NIKHOLLI MARCELLE LEMOS | O8: PARAMETRIZAR CAMPANHA - 2911 E 11402 - ABRIL 2025 | P8: 45754 | Q8: CREDITO PARA O 2911
A9: 2- MANUAL | B9: 8488 | C9: 08 - AGOSTO | D9: 2911 | 11402 | E9: 45870 | F9: 45900 | G9: BANCO FACTA - CONFORME REGULAMENTO | H9: MENSAL | I9: 0.01 | J9: 0.002 | M9: FILIAL VITORIA | N9: NIKHOLLI MARCELLE LEMOS | O9: PARAMETRIZAR CAMPANHA - 2911 E 11402 - ABRIL 2025 | P9: 45754 | Q9: CREDITO PARA O 2911
A10: 2- MANUAL | B10: 6756 | C10: 08 - AGOSTO | D10: 2598 | E10: 45870 | F10: 45900 | G10: TODOS OS BANCOS E TODOS OS PRODUTOS. Exceto banco BMG E ITAU E TABELAS QUE POSSUEM REGRAS VIP APROVADAS) | H10: MENSAL | I10: 0.01 | J10: 0.0025 | M10: FILIAL BH1 | N10: CAROLINE ADRIANA DOS SANTOS BRAGA | O10: PARAMETRIZAR CAMPANHA - ID: 2598 - REF: MAIO 2025 | P10: 45779
A11: 1- AUTOMÁTICO | B11: 7186 | C11: 08 - AGOSTO | D11: 936 | E11: 45870 | F11: 45900 | G11: LOTUS FGTS | H11: MENSAL | I11: 500000 | J11: 0.002 | M11: FILIAL BH2 | N11: ALESSANDRO MACHADO DA SILVA | O11: PARAMETRIZAR CAMPAHA - ID: 936 - REF: JUNHO | P11: 45824
A12: 1- AUTOMÁTICO | B12: 7805 | C12: 08 - AGOSTO | D12: 936 | E12: 45870 | F12: 45900 | G12: LOTUS FGTS | H12: MENSAL | I12: 0.01 | J12: 0.0055 | M12: FILIAL BH2 | N12: ALESSANDRO MACHADO DA SILVA | O12: PARAMETRIZAR CAMPAHA - ID: 936 - REF: JUNHO | P12: 45824
A13: 1- AUTOMÁTICO | B13: 7258 | C13: 08 - AGOSTO | D13: 17354 | E13: 45870 | F13: 45900 | G13: TODA OPERAÇÃO CASH CARD | H13: MENSAL | I13: 0.01 | J13: 0.006 | M13: FILIAL CUIABA | N13: JULIANA DE ALMEIDA SIMPLICIO ROCHA | O13: PARAMETRIZAR CAMPANHA - ID 17353 - CASH CARD | P13: 45828
A14: 2- MANUAL | B14: 7509 | C14: 08 - AGOSTO | D14: 12340 | E14: 45870 | F14: 45900 | G14: TODA A PRODUÇÃO PARA ATINGIMENTO - PAGAMENTO PARA TODA A PRODUÇÃO - EXCETO BMG - VIP | H14: MENSAL | I14: 300000 | J14: 0.0005 | M14: FILIAL UBERLANDIA | N14: MATHEUS REZENDE SUDRE | O14: PARAMETRIZAR CAMPANHA ID 12340 - REF: JULHO 2025 | P14: 45849
A15: 2- MANUAL | B15: 7509 | C15: 08 - AGOSTO | D15: 12340 | E15: 45870 | F15: 45900 | G15: TODA A PRODUÇÃO PARA ATINGIMENTO - PAGAMENTO PARA TODA A PRODUÇÃO - EXCETO BMG - VIP | H15: MENSAL | I15: 500000 | J15: 0.001 | M15: FILIAL UBERLANDIA | N15: MATHEUS REZENDE SUDRE | O15: PARAMETRIZAR CAMPANHA ID 12340 - REF: JULHO 2025 | P15: 45849
A16: 1- AUTOMÁTICO | B16: 7513 | C16: 08 - AGOSTO | D16: 4079 | E16: 45870 | F16: 45900 | G16: MEU CREDBANK - INSS - MEU CREDBANK - INSS - FP - SEGURO TOP - TAXA 1,85 / MEU CREDBANK - INSS - MEU CREDBANK - INSS - FP - SEGURO - TX 1,85 / MEU CREDBANK - INSS - MEU CREDBANK - INSS - FP - SEGURO FLEX | H16: MENSAL | I16: 0.01 | J16: 0.005 | M16: FILIAL UBERLANDIA | N16: JOAO EURICO PINHEIRO IGNACIO DOS SANTOS | O16: PARAMETRIZAR CAMPANHA - ID 4079 - BANCO MEU CREDBANK | P16: 45849
A17: 2- MANUAL | B17: 7535 | C17: 08 - AGOSTO | D17: 17894 | E17: 45870 | F17: 45900 | G17: BANCO FACTA - CONFORME REGULAMENTO | H17: MENSAL | I17: 0.01 | J17: 0.0075 | M17: FILIAL UBERLANDIA | N17: JOAO EURICO PINHEIRO IGNACIO DOS SANTOS | O17: PARAMETRIZACAO CAMPANHA I BANCO FACTA I COD 17894 - JULHO | P17: 45845
A18: 2- MANUAL | B18: 7114 | C18: 08 - AGOSTO | D18: 4079 | E18: 45809 | F18: 45900 | G18: BANCO FACTA - CONFORME REGULAMENTO | H18: MENSAL | I18: 0.01 | J18: 0.0075 | M18: FILIAL UBERLANDIA | N18: JOAO EURICO PINHEIRO IGNACIO DOS SANTOS | O18: PARAMETRIZAR CAMPANHA - ID: 4079 - | P18: 45819
A19: 1- AUTOMÁTICO | B19: 7694 | C19: 08 - AGOSTO | D19: 7460 | 12006 | E19: 45870 | F19: 45900 | G19: CONSIDERAR TODA A PRODUÇAO PARA APURAÇAO DA META E bonificacao | H19: MENSAL | I19: 800000 | J19: 0.001 | M19: FILIAL UBERLANDIA | N19: JOAO EURICO PINHEIRO IGNACIO DOS SANTOS | O19: PARAMETRIZAR CAMPANHA - 7460 / 12006 | P19: 45854 | Q19: CREDITO PARA O 7460
A20: 1- AUTOMÁTICO | B20: 7811 | C20: 08 - AGOSTO | D20: 4190 | E20: 45870 | F20: 45900 | G20: CONSIDERAR TODA A PRODUÇAO DO DIGIO PARA APURAÇAO. | H20: MENSAL | I20: 2000 | J20: 0.002 | M20: FILIAL UBERLANDIA | N20: MATHEUS REZENDE SUDRE | O20: PARAMETRIZAR CAMPANHA - ID 4190 | P20: 45862
A21: 1- AUTOMÁTICO | B21: 7814 | C21: 08 - AGOSTO | D21: 4190 | E21: 45870 | F21: 45900 | G21: CONSIDERAR TODA A PRODUÇAO DO SAFRA PARA APURAÇAO. | H21: MENSAL | I21: 2000 | J21: 0.002 | M21: FILIAL UBERLANDIA | N21: MATHEUS REZENDE SUDRE | O21: PARAMETRIZAR CAMPANHA - ID 4190 | P21: 45862
A22: 2- MANUAL | B22: 7817 | C22: 08 - AGOSTO | D22: 4190 | E22: 45870 | F22: 45900 | G22: BANCO FACTA - CONFORME REGULAMENTO | H22: MENSAL | I22: 2000 | J22: 0.002 | M22: FILIAL UBERLANDIA | N22: MATHEUS REZENDE SUDRE | O22: PARAMETRIZAR CAMPANHA - ID 4190 | P22: 45862
A23: 1- AUTOMÁTICO | B23: 7820 | C23: 08 - AGOSTO | D23: 4190 | E23: 45870 | F23: 45900 | G23: CONSIDERAR TODA A PRODUÇAO DO BANRISUL PARA APURAÇAO. | H23: MENSAL | I23: 2000 | J23: 0.002 | M23: FILIAL UBERLANDIA | N23: MATHEUS REZENDE SUDRE | O23: PARAMETRIZAR CAMPANHA - ID 4190 | P23: 45862
A24: 1- AUTOMÁTICO | B24: 7824 | C24: 08 - AGOSTO | D24: 4190 | E24: 45870 | F24: 45900 | G24: CONSIDERAR TODA A PRODUÇAO DO BMG PARA APURAÇAO. | H24: MENSAL | I24: 2000 | J24: 0.002 | M24: FILIAL UBERLANDIA | N24: MATHEUS REZENDE SUDRE | O24: PARAMETRIZAR CAMPANHA - ID 4190 | P24: 45862
A25: 1- AUTOMÁTICO | B25: 7827 | C25: 08 - AGOSTO | D25: 4190 | E25: 45870 | F25: 45900 | G25: CONSIDERAR TODA A PRODUÇAO DO PAN PARA APURAÇAO. | H25: MENSAL | I25: 2000 | J25: 0.002 | M25: FILIAL UBERLANDIA | N25: MATHEUS REZENDE SUDRE | O25: PARAMETRIZAR CAMPANHA - ID 4190 | P25: 45862
A26: 1- AUTOMÁTICO | B26: 7830 | C26: 08 - AGOSTO | D26: 4190 | E26: 45870 | F26: 45900 | G26: CONSIDERAR TODA A PRODUÇAO DO MEU CREDBANKPARA APURAÇAO. | H26: MENSAL | I26: 2000 | J26: 0.002 | M26: FILIAL UBERLANDIA | N26: MATHEUS REZENDE SUDRE | O26: PARAMETRIZAR CAMPANHA - ID 4190 | P26: 45862
A27: 1- AUTOMÁTICO | B27: 7839 | C27: 08 - AGOSTO | D27: 7337 | E27: 45860 | F27: 45891 | G27: BMG -TODA A PRODUÇÃO | H27: FINAL DE CAMPANHA | I27: 0.01 | J27: 0.02 | M27: FILIAL PORTO ALEGRE | N27: GUSTAVO DANERES BERNEIRA | O27: PARAMETRIZAR CAMPANH - BANCO BMG - ID 7337 | P27: 45861
A28: 1- AUTOMÁTICO | B28: 7833 | C28: 08 - AGOSTO | D28: 2404 | E28: 45870 | F28: 45900 | G28: DAYCOVAL - PORTABILIDADE NOS CONVENIOS SEPLAG / PMMG / IPSM / IPSEMG | H28: MENSAL | I28: 0.01 | J28: 0.005 | M28: FILIAL MC | N28: MAURICIO PEREIRA DOS SANTOS | O28: PARAMETRIZAR CAMPANHA - ID 2404 - PORTABILIDADE DAYCOVAL | P28: 45862
A29: 1- AUTOMÁTICO | B29: 7846 | C29: 08 - AGOSTO | D29: 13891 | E29: 45870 | F29: 45900 | G29: TODA A PRODUÇÃO BANCO MASTER | H29: MENSAL | I29: 0.01 | J29: 0.0125 | M29: FILIAL PORTO ALEGRE | N29: GUSTAVO DANERES BERNEIRA | O29: CAMPANHA BANCO MASTER I JUNHO-AGOSTO I ANDRÉ MEDEIROS | P29: 45862
A30: 2- MANUAL | B30: 6166 | C30: 08 - AGOSTO | D30: 3184 | 12430 | E30: 45870 | F30: 45900 | G30: TODA A PRODUÇÃO PARA ATINGIR A META E CONTABILIZAR-META DESCONSIDERAR BMG E C6 ( INSS /NOVO ) | H30: MENSAL | I30: 300000 | J30: 0.002 | M30: FILIAL BH2 | N30: TIAGO ROGANA FERNANDES | O30: PARAMETRIZAR CAMPANHA - ID 3184/12430 | P30: 45721 | Q30: CREDITO PARA O 3184
A31: 2- MANUAL | B31: 7928 | C31: 08 - AGOSTO | D31: 17711 | E31: 45870 | F31: 45900 | G31: BANCO FACTA - CONFORME REGULAMENTO | H31: MENSAL | I31: 0.01 | J31: 0.0075 | M31: FILIAL SP CAPITAL | N31: GUSTAVO ANDRÉ FERRARI | O31: 1744911 | P31: 45874
A32: 2- MANUAL | B32: 7927 | C32: 08 - AGOSTO | D32: 16898 | E32: 45870 | F32: 45900 | G32: BANCO FACTA - CONFORME REGULAMENTO | H32: MENSAL | I32: 0.01 | J32: 0.0045 | M32: FILIAL SP CAPITAL | N32: GUSTAVO ANDRÉ FERRARI | O32: 1744845 | P32: 45874.6
A33: 1- AUTOMÁTICO | B33: 7926 | C33: 08 - AGOSTO | D33: 14363 | E33: 45870 | F33: 45900 | G33: TODA A PRODUÇÃO DOS CARTÕES RMC E RCC SIAPE - QUERO MAIS CRÉDITO | H33: MENSAL | I33: 1000 | J33: 0.015 | M33: FILIAL FLORIANOPOLIS | N33: JULIO CEZAR DE PAULA ALANO | O33: 1743157 | P33: 45870.735
A34: 2- MANUAL | B34: 7925 | C34: 08 - AGOSTO | D34: 17253 | E34: 45870 | F34: 45900 | G34: BANCO FACTA - CONFORME REGULAMENTO | H34: MENSAL | I34: 0.01 | J34: 0.0075 | M34: FILIAL RJ | N34: IGOR DE ALMEIDA RODRIGUES | O34: 1744722 | P34: 45874.535
A35: 2- MANUAL | B35: 7924 | C35: 08 - AGOSTO | D35: 14129 | E35: 45870 | F35: 45900 | G35: BANCO FACTA - CONFORME REGULAMENTO | H35: MENSAL | I35: 0.01 | J35: 0.0075 | M35: FILIAL RJ | N35: IGOR DE ALMEIDA RODRIGUES | O35: 1744722 | P35: 45874.535
A36: 2- MANUAL | B36: 7923 | C36: 08 - AGOSTO | D36: 2240 | E36: 45870 | F36: 45900 | G36: BANCO FACTA - CONFORME REGULAMENTO | H36: MENSAL | I36: 0.01 | J36: 0.0075 | M36: FILIAL RJ | N36: IGOR DE ALMEIDA RODRIGUES | O36: 1744722 | P36: 45874.535
A37: 1- AUTOMÁTICO | B37: 7922 | C37: 08 - AGOSTO | D37: 17714 | E37: 45870 | F37: 45900 | G37: (PRODUÇÃO GERAL BANCO MASTER) | H37: MENSAL | I37: 1000 | J37: 0.0045 | M37: FILIAL RJ | N37: IGOR DE ALMEIDA RODRIGUES | O37: 1744722 | P37: 45874.535
A38: 1- AUTOMÁTICO | B38: 7921 | C38: 08 - AGOSTO | D38: 14129 | E38: 45870 | F38: 45900 | G38: (PRODUÇÃO GERAL BANCO DÍGIO) | H38: 0 | I38: 1000 | J38: 0.005 | M38: FILIAL RJ | N38: IGOR DE ALMEIDA RODRIGUES | O38: 1744722 | P38: 45874.535
A39: 2- MANUAL | B39: 7920 | C39: 08 - AGOSTO | D39: 8835 | E39: 45870 | F39: 45900 | G39: BANCO FACTA - INSS / FGTS - CONFORME REGULAMENTO | H39: MENSAL | I39: 0.01 | J39: 0.006 | M39: FILIAL SP CAPITAL | N39: DANIELA PRADO BULDO | O39: 1744703 | P39: 45874.525
A40: 2- MANUAL | B40: 7919 | C40: 08 - AGOSTO | D40: 13929 | E40: 45870 | F40: 45900 | G40: BANCO FACTA - INSS / FGTS - CONFORME REGULAMENTO | H40: MENSAL | I40: 0.01 | J40: 0.006 | M40: FILIAL SP CAPITAL | N40: DANIELA PRADO BULDO | O40: 1744571 | P40: 45874.471
...

Sheet JUL - 25
A1: Nº | B1: FECHAMENTO | C1: COD | D1: INICIO | E1: FIM | F1: PERÍODO FECHAMENTO | G1: META | H1: PRÊMIO GANHO | I1: FILIAL | J1: SOLICITAÇÃO (E-MAIL) | K1: ASSUNTO (E-MAIL) | L1: PARÂMETRO
A2: 894 | C2: 10452 | D2: 45748 | E2: 45777 | F2: MENSAL | G2: 200000 | H2: 0.002 | I2: FILIAL PORTO ALEGRE | J2: 45756 | K2: PARAMETRIZAÇÃO CAMPANHA I BANCO FACTA I COD 10452 I ABRIL | L2: BANCO FACTA - CONFORME REGULAMENTO
A3: 895 | C3: 10452 | D3: 45748 | E3: 45777 | F3: MENSAL | G3: 300000 | H3: 0.003 | I3: FILIAL PORTO ALEGRE | J3: 45756 | K3: PARAMETRIZAÇÃO CAMPANHA I BANCO FACTA I COD 10452 I ABRIL | L3: BANCO FACTA - CONFORME REGULAMENTO
A4: 896 | C4: 10452 | D4: 45748 | E4: 45777 | F4: MENSAL | G4: 400000 | H4: 0.004 | I4: FILIAL PORTO ALEGRE | J4: 45756 | K4: PARAMETRIZAÇÃO CAMPANHA I BANCO FACTA I COD 10452 I ABRIL | L4: BANCO FACTA - CONFORME REGULAMENTO
A5: 897 | C5: 10452 | D5: 45748 | E5: 45777 | F5: MENSAL | G5: 500000 | H5: 0.005 | I5: FILIAL PORTO ALEGRE | J5: 45756 | K5: PARAMETRIZAÇÃO CAMPANHA I BANCO FACTA I COD 10452 I ABRIL | L5: BANCO FACTA - CONFORME REGULAMENTO
A6: 985 | C6: 3349 / 11938 | D6: 45748 | E6: 45777 | F6: MENSAL | G6: 500000 | H6: 0.002 | I6: FILIAL UBERLANDIA | J6: 45761 | K6: PARAMETRIZAR CAMPANHA - 3349 E 11938 sub | L6: TODA PRODUCAO PARA CONTABILIZAR -META INSS-NOVO-84X -EXCETO ITAU-CREDITO 11938
A7: 1166 | C7: 8465/1363/3728/3729 | D7: 45748 | E7: 45808 | F7: FINAL DE CAMPANHA | G7: 1000000 | H7: 0.02 | I7: FILIAL BH1 | J7: 45749 | K7: PARAMETRIZAR CAMPANHA - ID 8465/1363/3728/3729 - BANCO AMIGOZ | L7: TODA A PRODUÇÃO AMIGOZ-CREDITO o 8465.
A8: 1171 | C8: 1212 | D8: 45778 | E8: 45808 | F8: MENSAL | G8: 500000 | H8: 0.005 | I8: FILIAL UBERLANDIA | J8: 45764 | K8: PARAMETRIZAR CAMPANHA - ID: 1212 - REF: ABRIL E MAIO | L8: BANCO DIGIO CONVENIO SIAPE
A9: 1233 | C9: 16995 | D9: 45778 | E9: 45808 | F9: MENSAL | G9: 200000 | H9: 0.004 | I9: FILIAL PORTO ALEGRE | J9: 45783 | K9: PARAMETRIZAÇÃO CAMPANHA I BANCO FACTA I COD 16995 -MAIO | L9: FACTA CONFORME REGULAMENTO
A10: 1234 | C10: 16995 | D10: 45778 | E10: 45808 | F10: MENSAL | G10: 100000 | H10: 0.003 | I10: FILIAL PORTO ALEGRE | J10: 45783 | K10: PARAMETRIZAÇÃO CAMPANHA I BANCO FACTA I COD 16995 -MAIO | L10: FACTA CONFORME REGULAMENTO
A11: 1237 | C11: 17421 | D11: 45778 | E11: 45808 | F11: MENSAL | G11: 200000 | H11: 0.004 | I11: FILIAL PORTO ALEGRE | J11: 45783 | K11: PARAMETRIZAR CAMPANHA I BANCO FACTA I COD 17421 - MAIO | L11: FACTA CONFORME REGULAMENTO
A12: 1238 | C12: 17421 | D12: 45778 | E12: 45808 | F12: MENSAL | G12: 100000 | H12: 0.003 | I12: FILIAL PORTO ALEGRE | J12: 45783 | K12: PARAMETRIZAR CAMPANHA I BANCO FACTA I COD 17421 - MAIO | L12: FACTA CONFORME REGULAMENTO
A13: 1248 | C13: 10649 | D13: 45778 | E13: 45808 | F13: MENSAL | G13: 200000 | H13: 0.003 | I13: FILIAL RJ | J13: 45784 | K13: PARAMETRIZAR CAMPANHA - GC IGOR | L13: PRODUCAO TOTAL ATINGIR A META-BONIFICACAO NOVOS INSS C 6 ,FACTA , CREDBANK, PRESENÇA E VCTEX
A14: 1336 | C14: 16955 | D14: 45778 | E14: 45808 | F14: MENSAL | G14: 800000 | H14: 0.003 | I14: FILIAL PORTO ALEGRE | J14: 45793 | K14: CAMPANHA BANCO FACTA I 16955 I MAIO | L14: Banco Facta - Novo, cartão, FGTS, refin da port - parcelas todas
A15: 1337 | C15: 16955 | D15: 45778 | E15: 45808 | F15: MENSAL | G15: 1000000 | H15: 0.004 | I15: FILIAL PORTO ALEGRE | J15: 45793 | K15: CAMPANHA BANCO FACTA I 16955 I MAIO | L15: Banco Facta - Novo, cartão, FGTS, refin da port - parcelas todas
A16: 1338 | C16: 16955 | D16: 45778 | E16: 45808 | F16: MENSAL | G16: 1500000 | H16: 0.005 | I16: FILIAL PORTO ALEGRE | J16: 45793 | K16: CAMPANHA BANCO FACTA I 16955 I MAIO | L16: Banco Facta - Novo, cartão, FGTS, refin da port - parcelas todas
A17: 1484 | C17: 6843 | D17: 45778 | E17: 45808 | F17: MENSAL | G17: 0.01 | H17: 0.002 | I17: FILIAL UBERLANDIA | J17: 45805 | K17: PARAMETRIZAR CAMPANHAS 6843 | MAIO | BANCO DIGIO | L17: DIGIO - TODA PRODUÇÃO NÃO LANÇAR CRÉDITO, PARA REGISTRO INTERNO E ABATIMENTO DE DÍVIDA DO CÓDIGO 1419.
A18: 1848 | B18: 07 - JULHO | C18: 12765 | D18: 45839 | E18: 45869 | F18: MENSAL | G18: 1000000 | H18: 0 | I18: 0 | J18: 45740 | K18: Re: Antecipação de valores RL Rangel Serviços LTDA - 12765 (Projeto de ampliação Call Center) | L18: TODA PRODUÇÃO - CASO ATINJA OU NÃO, APENAS RETORNAR NO E-MAIL COMUNICANDO A PRODUÇÃO
A19: 1849 | B19: 07 - JULHO | C19: 17740 | D19: 45839 | E19: 45858 | F19: MENSAL | G19: 0.01 | H19: 0.005 | I19: FILIAL VITORIA | J19: 45854 | K19: CAMPANHA MES JULHO I BANCO MERCANTIL I COD 17740 | L19: BANCO MERCANTIL - Bônus pago referente a venda de cartão RMC E RCC
A20: 1850 | B20: 07 - JULHO | C20: 13718 | D20: 45839 | E20: 45869 | F20: MENSAL | G20: 0.01 | H20: 0.005 | I20: FILIAL BH2 | J20: 45855 | K20: CAMPANHA MES JULHO I COD 13718 | L20: BANCO PRESENÇA - INSS - TODA A PRODUÇÃO
A21: 1851 | B21: 07 - JULHO | C21: 13718 | D21: 45839 | E21: 45869 | F21: MENSAL | G21: 0.01 | H21: 0.035 | I21: FILIAL GOIANIA | J21: 45855 | K21: CAMPANHA MES JULHO I COD 13718 | L21: BANCO AMIGOZ - TODA A PRODUÇÃO EXCETO ( EXCETO PREF RECIFE / TJ MG / JUIZ DE FORA)
A22: 1852 | B22: 07 - JULHO | C22: 11820 | D22: 45839 | E22: 45869 | F22: MENSAL | G22: 0.01 | H22: 0.0075 | I22: FILIAL GOIANIA | J22: 45854 | K22: CAMPANHA MES JULHO I BANCO FACTA I COD 11820 | L22: Bonus pago em cima de contrato novo com seguro/prazo maximo e Refin port até a flex 2 ( Conforme parametro facta )
A23: 1853 | B23: 07 - JULHO | C23: 2619 | D23: 45839 | E23: 45869 | F23: MENSAL | G23: 0.01 | H23: 0.01 | I23: FILIAL BH2 | J23: 45847 | K23: PARAMETRIZAR CAMPANHA - ID 2619 - VCTEX | L23: BANCO VCTEX - TODA A PRODUÇÃO
A24: 1854 | B24: 07 - JULHO | C24: 3895 | D24: 45839 | E24: 45869 | F24: MENSAL | G24: 0.01 | H24: 0.005 | I24: FILIAL GOIANIA | J24: 45854 | K24: PARAMETRIZAR CAMPANHA - BANOC MERCANTIL - ID 3895 | L24: BANCO MERCANTIL - CARTÕES - GRUPO MINAS
A25: 1855 | B25: 07 - JULHO | C25: 17051 | D25: 45839 | E25: 45869 | F25: MENSAL | G25: 0.01 | H25: 0.0015 | I25: FILIAL BH2 | J25: 45854 | K25: CAMAPANHA MES JULHO I BANCO FACTA I COD 17051 | L25: Bonus pago em cima de contrato novo com seguro/prazo maximo e Refin port até a flex 2 ( Conforme parametro facta )
A26: 1856 | B26: 07 - JULHO | C26: 1452 | D26: 45839 | E26: 45869 | F26: MENSAL | G26: 300000 | H26: 0.001 | I26: FILIAL BH2 | J26: 45854 | K26: PARAMETRIZAR CAMPANHA - ID: 1452 - REF: JULHO 2025 | L26: TODA A PRODUÇÃO PARA ATINGIMENTO - TODA A PRODUÇÃO EXCETO ITAU PARA PAGAMENTO
A27: 1857 | B27: 07 - JULHO | C27: 3349 / 11938 | D27: 45839 | E27: 45869 | F27: MENSAL | G27: 300000 | H27: 0.001 | I27: FILIAL UBERLANDIA | J27: 45854 | K27: PARAMETRIZAR CAMPANHA - 11938 / 3349 | L27: TODA A PRODUÇÃO atingir a meta- bonificação TODA A PRODUÇÃO novo-inss-84x exceto banco itau.
A28: 1858 | B28: 07 - JULHO | C28: 3349 / 11938 | D28: 45839 | E28: 45869 | F28: MENSAL | G28: 500000 | H28: 0.002 | I28: FILIAL UBERLANDIA | J28: 45854 | K28: PARAMETRIZAR CAMPANHA - 11938 / 3349 | L28: TODA A PRODUÇÃO atingir a meta- bonificação TODA A PRODUÇÃO novo-inss-84x exceto banco itau.
